cpu-bind=MASK - n2gpu1202, task  0  0 [3830906]: mask |B-------|--------||--------|--------||--------|--------||--------|--------||||--------|--------||--------|--------||--------|--------||--------|--------|  set
cpu-bind=MASK - n2gpu1202, task  0  0 [3830940]: mask |B-------|--------||--------|--------||--------|--------||--------|--------||||--------|--------||--------|--------||--------|--------||--------|--------|  set
cpu-bind=MASK - n2gpu1203, task  1  0 [1054882]: mask |B-------|--------||--------|--------||--------|--------||--------|--------||||--------|--------||--------|--------||--------|--------||--------|--------|  set
WARNING:__main__:
*****************************************
Setting OMP_NUM_THREADS environment variable for each process to be 1 in default, to avoid your system being overloaded, please further tune the variable for optimal performance in your application as needed. 
*****************************************
WARNING:__main__:
*****************************************
Setting OMP_NUM_THREADS environment variable for each process to be 1 in default, to avoid your system being overloaded, please further tune the variable for optimal performance in your application as needed. 
*****************************************
[default0]:/scratch/hpc-prf-lola/lib_repo/conda-libs/envs/lola/bin/python: can't open file '/scratch/hpc-prf-lola/nikit/repos/Megatron-DeepSpeed-BigScience/python': [Errno 2] No such file or directory
[default1]:/scratch/hpc-prf-lola/lib_repo/conda-libs/envs/lola/bin/python: can't open file '/scratch/hpc-prf-lola/nikit/repos/Megatron-DeepSpeed-BigScience/python': [Errno 2] No such file or directory
[default3]:/scratch/hpc-prf-lola/lib_repo/conda-libs/envs/lola/bin/python: can't open file '/scratch/hpc-prf-lola/nikit/repos/Megatron-DeepSpeed-BigScience/python': [Errno 2] No such file or directory
[default2]:/scratch/hpc-prf-lola/lib_repo/conda-libs/envs/lola/bin/python: can't open file '/scratch/hpc-prf-lola/nikit/repos/Megatron-DeepSpeed-BigScience/python': [Errno 2] No such file or directory
[default0]:/scratch/hpc-prf-lola/lib_repo/conda-libs/envs/lola/bin/python: can't open file '/scratch/hpc-prf-lola/nikit/repos/Megatron-DeepSpeed-BigScience/python': [Errno 2] No such file or directory
[default2]:/scratch/hpc-prf-lola/lib_repo/conda-libs/envs/lola/bin/python: can't open file '/scratch/hpc-prf-lola/nikit/repos/Megatron-DeepSpeed-BigScience/python': [Errno 2] No such file or directory
[default3]:/scratch/hpc-prf-lola/lib_repo/conda-libs/envs/lola/bin/python: can't open file '/scratch/hpc-prf-lola/nikit/repos/Megatron-DeepSpeed-BigScience/python': [Errno 2] No such file or directory
[default1]:/scratch/hpc-prf-lola/lib_repo/conda-libs/envs/lola/bin/python: can't open file '/scratch/hpc-prf-lola/nikit/repos/Megatron-DeepSpeed-BigScience/python': [Errno 2] No such file or directory
ERROR:torch.distributed.elastic.multiprocessing.api:failed (exitcode: 2) local_rank: 0 (pid: 1054905) of binary: /scratch/hpc-prf-lola/lib_repo/conda-libs/envs/lola/bin/python
ERROR:torch.distributed.elastic.multiprocessing.api:failed (exitcode: 2) local_rank: 0 (pid: 3830976) of binary: /scratch/hpc-prf-lola/lib_repo/conda-libs/envs/lola/bin/python
Traceback (most recent call last):
  File "/scratch/hpc-prf-lola/lib_repo/conda-libs/envs/lola/lib/python3.9/runpy.py", line 197, in _run_module_as_main
Traceback (most recent call last):
  File "/scratch/hpc-prf-lola/lib_repo/conda-libs/envs/lola/lib/python3.9/runpy.py", line 197, in _run_module_as_main
    return _run_code(code, main_globals, None,
  File "/scratch/hpc-prf-lola/lib_repo/conda-libs/envs/lola/lib/python3.9/runpy.py", line 87, in _run_code
    return _run_code(code, main_globals, None,
  File "/scratch/hpc-prf-lola/lib_repo/conda-libs/envs/lola/lib/python3.9/runpy.py", line 87, in _run_code
    exec(code, run_globals)
  File "/scratch/hpc-prf-lola/lib_repo/conda-libs/envs/lola/lib/python3.9/site-packages/torch/distributed/run.py", line 766, in <module>
    main()
  File "/scratch/hpc-prf-lola/lib_repo/conda-libs/envs/lola/lib/python3.9/site-packages/torch/distributed/elastic/multiprocessing/errors/__init__.py", line 346, in wrapper
    exec(code, run_globals)
  File "/scratch/hpc-prf-lola/lib_repo/conda-libs/envs/lola/lib/python3.9/site-packages/torch/distributed/run.py", line 766, in <module>
    return f(*args, **kwargs)
  File "/scratch/hpc-prf-lola/lib_repo/conda-libs/envs/lola/lib/python3.9/site-packages/torch/distributed/run.py", line 762, in main
    main()
  File "/scratch/hpc-prf-lola/lib_repo/conda-libs/envs/lola/lib/python3.9/site-packages/torch/distributed/elastic/multiprocessing/errors/__init__.py", line 346, in wrapper
    run(args)
  File "/scratch/hpc-prf-lola/lib_repo/conda-libs/envs/lola/lib/python3.9/site-packages/torch/distributed/run.py", line 753, in run
    elastic_launch(
  File "/scratch/hpc-prf-lola/lib_repo/conda-libs/envs/lola/lib/python3.9/site-packages/torch/distributed/launcher/api.py", line 132, in __call__
    return f(*args, **kwargs)
  File "/scratch/hpc-prf-lola/lib_repo/conda-libs/envs/lola/lib/python3.9/site-packages/torch/distributed/run.py", line 762, in main
    return launch_agent(self._config, self._entrypoint, list(args))
  File "/scratch/hpc-prf-lola/lib_repo/conda-libs/envs/lola/lib/python3.9/site-packages/torch/distributed/launcher/api.py", line 246, in launch_agent
    run(args)
  File "/scratch/hpc-prf-lola/lib_repo/conda-libs/envs/lola/lib/python3.9/site-packages/torch/distributed/run.py", line 753, in run
    raise ChildFailedError(
torch.distributed.elastic.multiprocessing.errors.ChildFailedError: 
============================================================
python FAILED
------------------------------------------------------------
Failures:
[1]:
  time      : 2023-02-25_14:58:06
  host      : n2gpu1203.ab2021.local
  rank      : 5 (local_rank: 1)
  exitcode  : 2 (pid: 1054906)
  error_file: <N/A>
  traceback : To enable traceback see: https://pytorch.org/docs/stable/elastic/errors.html
[2]:
  time      : 2023-02-25_14:58:06
  host      : n2gpu1203.ab2021.local
  rank      : 6 (local_rank: 2)
  exitcode  : 2 (pid: 1054907)
  error_file: <N/A>
  traceback : To enable traceback see: https://pytorch.org/docs/stable/elastic/errors.html
[3]:
  time      : 2023-02-25_14:58:06
  host      : n2gpu1203.ab2021.local
  rank      : 7 (local_rank: 3)
  exitcode  : 2 (pid: 1054908)
  error_file: <N/A>
  traceback : To enable traceback see: https://pytorch.org/docs/stable/elastic/errors.html
------------------------------------------------------------
Root Cause (first observed failure):
[0]:
  time      : 2023-02-25_14:58:06
  host      : n2gpu1203.ab2021.local
  rank      : 4 (local_rank: 0)
  exitcode  : 2 (pid: 1054905)
  error_file: <N/A>
  traceback : To enable traceback see: https://pytorch.org/docs/stable/elastic/errors.html
============================================================
    elastic_launch(
  File "/scratch/hpc-prf-lola/lib_repo/conda-libs/envs/lola/lib/python3.9/site-packages/torch/distributed/launcher/api.py", line 132, in __call__
    return launch_agent(self._config, self._entrypoint, list(args))
  File "/scratch/hpc-prf-lola/lib_repo/conda-libs/envs/lola/lib/python3.9/site-packages/torch/distributed/launcher/api.py", line 246, in launch_agent
    raise ChildFailedError(
torch.distributed.elastic.multiprocessing.errors.ChildFailedError: 
============================================================
python FAILED
------------------------------------------------------------
Failures:
[1]:
  time      : 2023-02-25_14:58:06
  host      : n2gpu1202.ab2021.local
  rank      : 1 (local_rank: 1)
  exitcode  : 2 (pid: 3830977)
  error_file: <N/A>
  traceback : To enable traceback see: https://pytorch.org/docs/stable/elastic/errors.html
[2]:
  time      : 2023-02-25_14:58:06
  host      : n2gpu1202.ab2021.local
  rank      : 2 (local_rank: 2)
  exitcode  : 2 (pid: 3830978)
  error_file: <N/A>
  traceback : To enable traceback see: https://pytorch.org/docs/stable/elastic/errors.html
[3]:
  time      : 2023-02-25_14:58:06
  host      : n2gpu1202.ab2021.local
  rank      : 3 (local_rank: 3)
  exitcode  : 2 (pid: 3830979)
  error_file: <N/A>
  traceback : To enable traceback see: https://pytorch.org/docs/stable/elastic/errors.html
------------------------------------------------------------
Root Cause (first observed failure):
[0]:
  time      : 2023-02-25_14:58:06
  host      : n2gpu1202.ab2021.local
  rank      : 0 (local_rank: 0)
  exitcode  : 2 (pid: 3830976)
  error_file: <N/A>
  traceback : To enable traceback see: https://pytorch.org/docs/stable/elastic/errors.html
============================================================
srun: error: n2gpu1202: task 0: Exited with exit code 1
srun: launch/slurm: _step_signal: Terminating StepId=3096854.0
srun: error: n2gpu1203: task 1: Terminated
srun: Force Terminated StepId=3096854.0
