cpu-bind=MASK - n2gpu1212, task  0  0 [264727]: mask |BBBBBBBB|--------||--------|--------||--------|--------||--------|--------||||BBBBBBBB|--------||--------|--------||--------|--------||--------|--------|  set
cpu-bind=MASK - n2gpu1212, task  0  0 [264770]: mask |BBBBBBBB|--------||--------|--------||--------|--------||--------|--------||||BBBBBBBB|--------||--------|--------||--------|--------||--------|--------|  set
cpu-bind=MASK - n2gpu1213, task  1  0 [2022056]: mask |BBBBBBBB|--------||--------|--------||--------|--------||--------|--------||||BBBBBBBB|--------||--------|--------||--------|--------||--------|--------|  set
master_addr is only used for static rdzv_backend and when rdzv_endpoint is not specified.
master_addr is only used for static rdzv_backend and when rdzv_endpoint is not specified.
WARNING:torch.distributed.elastic.rendezvous.dynamic_rendezvous:The node 'n2gpu1213.ab2021.local_2022056_0' has failed to send a keep-alive heartbeat to the rendezvous 'none' due to an error of type RendezvousTimeoutError.
[default0]:Traceback (most recent call last):
[default0]:  File "/scratch/hpc-prf-lola/nikit/repos/Megatron-DeepSpeed-BigScience/pretrain_gpt.py", line 28, in <module>
[default0]:    from megatron.training import pretrain
[default0]:  File "/scratch/hpc-prf-lola/nikit/repos/Megatron-DeepSpeed-BigScience/megatron/training.py", line 43, in <module>
[default0]:    from megatron.optimizer import get_megatron_optimizer
[default0]:  File "/scratch/hpc-prf-lola/nikit/repos/Megatron-DeepSpeed-BigScience/megatron/optimizer/__init__.py", line 23, in <module>
[default0]:    from .optimizer import Float16OptimizerWithFloat16Params, FP32Optimizer
[default0]:  File "/scratch/hpc-prf-lola/nikit/repos/Megatron-DeepSpeed-BigScience/megatron/optimizer/optimizer.py", line 30, in <module>
[default0]:    from .clip_grads import clip_grad_norm_fp32, count_zeros_fp32
[default0]:  File "/scratch/hpc-prf-lola/nikit/repos/Megatron-DeepSpeed-BigScience/megatron/optimizer/clip_grads.py", line 19, in <module>
[default0]:    from torch._six import inf
[default0]:ModuleNotFoundError: No module named 'torch._six'
[default0]:Traceback (most recent call last):
[default0]:  File "/scratch/hpc-prf-lola/nikit/repos/Megatron-DeepSpeed-BigScience/pretrain_gpt.py", line 28, in <module>
[default0]:    from megatron.training import pretrain
[default0]:  File "/scratch/hpc-prf-lola/nikit/repos/Megatron-DeepSpeed-BigScience/megatron/training.py", line 43, in <module>
[default0]:    from megatron.optimizer import get_megatron_optimizer
[default0]:  File "/scratch/hpc-prf-lola/nikit/repos/Megatron-DeepSpeed-BigScience/megatron/optimizer/__init__.py", line 23, in <module>
[default0]:    from .optimizer import Float16OptimizerWithFloat16Params, FP32Optimizer
[default0]:  File "/scratch/hpc-prf-lola/nikit/repos/Megatron-DeepSpeed-BigScience/megatron/optimizer/optimizer.py", line 30, in <module>
[default0]:    from .clip_grads import clip_grad_norm_fp32, count_zeros_fp32
[default0]:  File "/scratch/hpc-prf-lola/nikit/repos/Megatron-DeepSpeed-BigScience/megatron/optimizer/clip_grads.py", line 19, in <module>
[default0]:    from torch._six import inf
[default0]:ModuleNotFoundError: No module named 'torch._six'
ERROR:torch.distributed.elastic.multiprocessing.api:failed (exitcode: 1) local_rank: 0 (pid: 264861) of binary: /scratch/hpc-prf-lola/lib_repo/conda-libs/envs/dstorch/bin/python
ERROR:torch.distributed.elastic.multiprocessing.api:failed (exitcode: 1) local_rank: 0 (pid: 2022153) of binary: /scratch/hpc-prf-lola/lib_repo/conda-libs/envs/dstorch/bin/python
Traceback (most recent call last):
  File "/scratch/hpc-prf-lola/lib_repo/conda-libs/envs/dstorch/lib/python3.9/runpy.py", line 197, in _run_module_as_main
    return _run_code(code, main_globals, None,
  File "/scratch/hpc-prf-lola/lib_repo/conda-libs/envs/dstorch/lib/python3.9/runpy.py", line 87, in _run_code
    exec(code, run_globals)
  File "/scratch/hpc-prf-lola/lib_repo/conda-libs/envs/dstorch/lib/python3.9/site-packages/torch/distributed/run.py", line 798, in <module>
    main()
  File "/scratch/hpc-prf-lola/lib_repo/conda-libs/envs/dstorch/lib/python3.9/site-packages/torch/distributed/elastic/multiprocessing/errors/__init__.py", line 346, in wrapper
    return f(*args, **kwargs)
  File "/scratch/hpc-prf-lola/lib_repo/conda-libs/envs/dstorch/lib/python3.9/site-packages/torch/distributed/run.py", line 794, in main
    run(args)
  File "/scratch/hpc-prf-lola/lib_repo/conda-libs/envs/dstorch/lib/python3.9/site-packages/torch/distributed/run.py", line 785, in run
    elastic_launch(
  File "/scratch/hpc-prf-lola/lib_repo/conda-libs/envs/dstorch/lib/python3.9/site-packages/torch/distributed/launcher/api.py", line 134, in __call__
    return launch_agent(self._config, self._entrypoint, list(args))
  File "/scratch/hpc-prf-lola/lib_repo/conda-libs/envs/dstorch/lib/python3.9/site-packages/torch/distributed/launcher/api.py", line 250, in launch_agent
    raise ChildFailedError(
torch.distributed.elastic.multiprocessing.errors.ChildFailedError: 
============================================================
pretrain_gpt.py FAILED
------------------------------------------------------------
Failures:
  <NO_OTHER_FAILURES>
------------------------------------------------------------
Root Cause (first observed failure):
[0]:
  time      : 2023-04-12_16:47:47
  host      : n2gpu1213.ab2021.local
  rank      : 1 (local_rank: 0)
  exitcode  : 1 (pid: 2022153)
  error_file: <N/A>
  traceback : To enable traceback see: https://pytorch.org/docs/stable/elastic/errors.html
============================================================
Traceback (most recent call last):
  File "/scratch/hpc-prf-lola/lib_repo/conda-libs/envs/dstorch/lib/python3.9/runpy.py", line 197, in _run_module_as_main
    return _run_code(code, main_globals, None,
  File "/scratch/hpc-prf-lola/lib_repo/conda-libs/envs/dstorch/lib/python3.9/runpy.py", line 87, in _run_code
    exec(code, run_globals)
  File "/scratch/hpc-prf-lola/lib_repo/conda-libs/envs/dstorch/lib/python3.9/site-packages/torch/distributed/run.py", line 798, in <module>
    main()
  File "/scratch/hpc-prf-lola/lib_repo/conda-libs/envs/dstorch/lib/python3.9/site-packages/torch/distributed/elastic/multiprocessing/errors/__init__.py", line 346, in wrapper
    return f(*args, **kwargs)
  File "/scratch/hpc-prf-lola/lib_repo/conda-libs/envs/dstorch/lib/python3.9/site-packages/torch/distributed/run.py", line 794, in main
    run(args)
  File "/scratch/hpc-prf-lola/lib_repo/conda-libs/envs/dstorch/lib/python3.9/site-packages/torch/distributed/run.py", line 785, in run
    elastic_launch(
  File "/scratch/hpc-prf-lola/lib_repo/conda-libs/envs/dstorch/lib/python3.9/site-packages/torch/distributed/launcher/api.py", line 134, in __call__
    return launch_agent(self._config, self._entrypoint, list(args))
  File "/scratch/hpc-prf-lola/lib_repo/conda-libs/envs/dstorch/lib/python3.9/site-packages/torch/distributed/launcher/api.py", line 250, in launch_agent
    raise ChildFailedError(
torch.distributed.elastic.multiprocessing.errors.ChildFailedError: 
============================================================
pretrain_gpt.py FAILED
------------------------------------------------------------
Failures:
  <NO_OTHER_FAILURES>
------------------------------------------------------------
Root Cause (first observed failure):
[0]:
  time      : 2023-04-12_16:47:20
  host      : n2gpu1212.ab2021.local
  rank      : 0 (local_rank: 0)
  exitcode  : 1 (pid: 264861)
  error_file: <N/A>
  traceback : To enable traceback see: https://pytorch.org/docs/stable/elastic/errors.html
============================================================
srun: error: n2gpu1212: task 0: Exited with exit code 1
srun: launch/slurm: _step_signal: Terminating StepId=3376783.0
srun: error: n2gpu1213: task 1: Exited with exit code 1
